Workbook

Sheet Dashboard
A1: สรุปผลการดำเนินงาน (Performance) สาขาลำพญากลาง ปีบัญชี 2568
A3: ชื่อ - นามสกุล | B3: ตำแหน่ง | C3: คะแนน Performance | D3: หมายเหตุ | E3: สถานะ
A4: นายภิชฌา ไทรทอง | B4: หัวหน้าหน่วยอำเภอ | C4: =ภิชฌา!O57 -> 31.962343
A5: นายพรพงศ์ สุวรรณวกุล | B5: พนักงานพัฒนาธุรกิจ 7 | C5: =พรพงศ์!O75 -> 65.321486
A6: นางพิราวรรณ สุวรรณนิตย์กุล | B6: พนักงานพัฒนาธุรกิจ 6 | C6: =พิราวรรณ!O75 -> 65.200286

Sheet ภิชฌา
A1: บันทึกข้อตกลงประเมินผลการปฏิบัติงานพนักงานรายคน ระดับ 1 - 9
A2: ปีบัญชี 2568
A4: ชื่อ - นามสกุล : | B4: นายภิชฌา ไทรทอง | C4: รหัสพนักงาน : | D4: 6000261 | F4: พนักงาน | I4: ผู้บังคับบัญชาเบื้องต้น | L4: ผู้บังคับบัญชาถัดไป
A5: ตำแหน่ง : | B5: หัวหน้าหน่วยอำเภอ | C5: สังกัดกลุ่มงาน :
A6: สาขา : | B6: ลำพญากลาง | C6: สนจ. : | D6: สระบุรี | F6: (นายภิชฌา ไทรทอง) | I6: (นางสาวลลิตา จีนไม้) | L6: (นางสาวใกล้รุ่ง หวังกั้นกลาง)
F7: ………………./………………./……………….. | I7: ………………./………………./……………….. | L7: ………………./………………./………………..
A10: หัวข้อประเมิน | F10: น้ำหนักคะแนน | G10: คะแนนประเมิน | I10: คะแนนประเมิน | K10: คะแนนเฉลี่ย | M10: หมายเหตุ
G11: ครั้งที่ 1 | I11: ครั้งที่ 2
A12: 1. ขีดความสามารถ (Competency) | F12: 20
A13: 2. การพัฒนาตนเอง (Self Development) | F13: 10 | G13: XX | I13: XX | K13: 10
A15: 3. ผลการดำเนินงาน (Performance) น้ำหนักคะแนน 70 คะแนน
A16: แผนงาน | C16: สนับสนุนยุทธศาสตร์ | D16: ประเภท | F16: ตัวชี้วัด | G16: น้ำหนัก | H16: เป้าหมาย | I16: ค่าคะแนน | N16: ผลงานจริง | O16: คะแนนที่ได้
C17: ยุทธศาสตร์ | D17: ทีม | E17: บุคคล | G17: คะแนน | I17: 1 | J17: 2 | K17: 3 | L17: 4* | M17: 5**
A18: งานสนับสนุนยุทธศาสตร์องค์กร / นโยบายสำคัญ | G18: XXX
A19: 1. รายได้FBI หมวด 1 –5 และสงเคราะห์ชีวิต | C19: 1 | D19: P | F19: ล้านบาท | G19: 2 | H19: 3.92 | I19: 2.06 | J19: 2.41 | K19: 2.75 | L19: 3.09 | M19: 3.92 | N19: =ผลงานรวมทีม!E58 -> 4.03 | O19: =((Q19/5)*G19) -> 2 | P19: ** | Q19: =IF(N19=0,0,IF(N19>=M19,5,IF(N19>=L19,5-ABS(M19-N19)/(M19-L19),IF(N19>=K19,4-ABS(L19-N19)/(L19-K19),IF(N19>=J19,3-ABS(K19-N19)/(K19-J19),IF(N19>=I19,2-ABS(J19-N19)/(J19-I19),1)))))) -> 5
A20: 2. การอนุมัติสินเชื่อใหม่ลูกค้าบุคคลธรรมดาและเกษตรกร (S2) | C20: 2 | D20: P | F20: ราย | G20: 2 | H20: 280 | I20: 193 | J20: 204 | K20: 248 | L20: 276 | M20: 280 | N20: =ผลงานรวมทีม!E11 -> 331 | O20: =((Q20/5)*G20) -> 2 | Q20: =IF(N20=0,0,IF(N20>=M20,5,IF(N20>=L20,5-ABS(M20-N20)/(M20-L20),IF(N20>=K20,4-ABS(L20-N20)/(L20-K20),IF(N20>=J20,3-ABS(K20-N20)/(K20-J20),IF(N20>=I20,2-ABS(J20-N20)/(J20-I20),1)))))) -> 5
A21: 3. โครงการพัฒนาทายาททดแทน | C21: 2 | D21: P | F21: ราย | G21: 2 | H21: 2 | I21: 0 | J21: 0 | K21: 0 | L21: 1 | M21: 2 | N21: =ผลงานรวมทีม!E12 -> 3 | O21: =((Q21/5)*G21) -> 2 | Q21: =IF(N21=0,0,IF(N21>=M21,5,IF(N21>=L21,5-ABS(M21-N21)/(M21-L21),IF(N21>=K21,4-ABS(L21-N21)/(L21-K21),IF(N21>=J21,3-ABS(K21-N21)/(K21-J21),IF(N21>=I21,2-ABS(J21-N21)/(J21-I21),1)))))) -> 5
A22: 4. Loan Growth | Q22: =IF(N22=0,0,IF(N22>=M22,5,IF(N22>=L22,5-ABS(M22-N22)/(M22-L22),IF(N22>=K22,4-ABS(L22-N22)/(L22-K22),IF(N22>=J22,3-ABS(K22-N22)/(K22-J22),IF(N22>=I22,2-ABS(J22-N22)/(J22-I22),1)))))) -> 0
A23: 4.1 การเติบโตสินเชื่อกลุ่มผลิตภัณฑ์ Secure Loan | C23: 2 | D23: P | F23: ล้านบาท | G23: 2.5 | H23: 8.73 | I23: 6.98 | J23: 7.42 | K23: 7.86 | L23: 8.29 | M23: 8.73 | N23: =ผลงานรวมทีม!E14 -> 10.28 | O23: =((Q23/5)*G23) -> 2.5 | Q23: =IF(N23=0,0,IF(N23>=M23,5,IF(N23>=L23,5-ABS(M23-N23)/(M23-L23),IF(N23>=K23,4-ABS(L23-N23)/(L23-K23),IF(N23>=J23,3-ABS(K23-N23)/(K23-J23),IF(N23>=I23,2-ABS(J23-N23)/(J23-I23),1)))))) -> 5
A24: 4.2 การเติบโตสินเชื่อ | C24: 2 | D24: P | F24: ล้านบาท | G24: 2 | H24: 8.45 | I24: 5.09 | J24: 5.92 | K24: 6.81 | L24: 7.61 | M24: 8.45 | N24: =ผลงานรวมทีม!E15 -> -204.38 | O24: =((Q24/5)*G24) -> 0.4 | Q24: =IF(N24=0,0,IF(N24>=M24,5,IF(N24>=L24,5-ABS(M24-N24)/(M24-L24),IF(N24>=K24,4-ABS(L24-N24)/(L24-K24),IF(N24>=J24,3-ABS(K24-N24)/(K24-J24),IF(N24>=I24,2-ABS(J24-N24)/(J24-I24),1)))))) -> 1
A25: งานตามภารกิจ (Job / Routine) | Q25: =IF(N25=0,0,IF(N25>=M25,5,IF(N25>=L25,5-ABS(M25-N25)/(M25-L25),IF(N25>=K25,4-ABS(L25-N25)/(L25-K25),IF(N25>=J25,3-ABS(K25-N25)/(K25-J25),IF(N25>=I25,2-ABS(J25-N25)/(J25-I25),1)))))) -> 0
A26: 5. อัตรารับชำระหนี้ เดือน เม.ย. 68 - มี.ค. 69 ณ.สิ้นเดือนที่ถึงกำหนดชำระ | Q26: =IF(N26=0,0,IF(N26>=M26,5,IF(N26>=L26,5-ABS(M26-N26)/(M26-L26),IF(N26>=K26,4-ABS(L26-N26)/(L26-K26),IF(N26>=J26,3-ABS(K26-N26)/(K26-J26),IF(N26>=I26,2-ABS(J26-N26)/(J26-I26),1)))))) -> 0
A27: 5.1 อัตรารับชำระหนี้ถึงกำหนดเดือน ต.ค. 2568 ณ.31 ต.ค.2568 | C27: 2 | D27: P | F27: ร้อยละ | G27: 0.5 | H27: 85 | I27: 77 | J27: 79 | K27: 81 | L27: 83 | M27: 85 | N27: =ผลงานรวมทีม!E24 -> 97.86 | O27: =((Q27/5)*G27) -> 0.5 | Q27: =IF(N27=0,0,IF(N27>=M27,5,IF(N27>=L27,5-ABS(M27-N27)/(M27-L27),IF(N27>=K27,4-ABS(L27-N27)/(L27-K27),IF(N27>=J27,3-ABS(K27-N27)/(K27-J27),IF(N27>=I27,2-ABS(J27-N27)/(J27-I27),1)))))) -> 5
A28: 5.2 อัตรารับชำระหนี้ถึงกำหนดเดือน พ.ย. 2568 ณ.30 พ.ย.2568 | C28: 2 | D28: P | F28: ร้อยละ | G28: 0.5 | H28: 85 | I28: 77 | J28: 79 | K28: 81 | L28: 83 | M28: 85 | N28: =ผลงานรวมทีม!E25 -> 97.99 | O28: =((Q28/5)*G28) -> 0.5 | Q28: =IF(N28=0,0,IF(N28>=M28,5,IF(N28>=L28,5-ABS(M28-N28)/(M28-L28),IF(N28>=K28,4-ABS(L28-N28)/(L28-K28),IF(N28>=J28,3-ABS(K28-N28)/(K28-J28),IF(N28>=I28,2-ABS(J28-N28)/(J28-I28),1)))))) -> 5
A29: 5.3 อัตรารับชำระหนี้ถึงกำหนดเดือน ธ.ค. 2568 ณ.31 ธ.ค.2568 | C29: 2 | D29: P | F29: ร้อยละ | G29: 0.5 | H29: 85 | I29: 77 | J29: 79 | K29: 81 | L29: 83 | M29: 85 | N29: =ผลงานรวมทีม!E26 -> 86.99 | O29: =((Q29/5)*G29) -> 0.5 | Q29: =IF(N29=0,0,IF(N29>=M29,5,IF(N29>=L29,5-ABS(M29-N29)/(M29-L29),IF(N29>=K29,4-ABS(L29-N29)/(L29-K29),IF(N29>=J29,3-ABS(K29-N29)/(K29-J29),IF(N29>=I29,2-ABS(J29-N29)/(J29-I29),1)))))) -> 5
A30: 5.4 อัตรารับชำระหนี้ถึงกำหนดเดือน ม.ค. 2569 ณ.31 ม.ค.2569 | C30: 2 | D30: P | F30: ร้อยละ | G30: 0.5 | H30: 85 | I30: 77 | J30: 79 | K30: 81 | L30: 83 | M30: 85 | N30: =ผลงานรวมทีม!E27 -> 97.53 | O30: =((Q30/5)*G30) -> 0.5 | Q30: =IF(N30=0,0,IF(N30>=M30,5,IF(N30>=L30,5-ABS(M30-N30)/(M30-L30),IF(N30>=K30,4-ABS(L30-N30)/(L30-K30),IF(N30>=J30,3-ABS(K30-N30)/(K30-J30),IF(N30>=I30,2-ABS(J30-N30)/(J30-I30),1)))))) -> 5
A31: 5.5 อัตรารับชำระหนี้ถึงกำหนดเดือน ก.พ. 2569 ณ.28 ก.พ.2569 | C31: 2 | D31: P | F31: ร้อยละ | G31: 0.5 | H31: 85 | I31: 77 | J31: 79 | K31: 81 | L31: 83 | M31: 85 | N31: =ผลงานรวมทีม!E28 -> 98.13 | O31: =((Q31/5)*G31) -> 0.5 | Q31: =IF(N31=0,0,IF(N31>=M31,5,IF(N31>=L31,5-ABS(M31-N31)/(M31-L31),IF(N31>=K31,4-ABS(L31-N31)/(L31-K31),IF(N31>=J31,3-ABS(K31-N31)/(K31-J31),IF(N31>=I31,2-ABS(J31-N31)/(J31-I31),1)))))) -> 5
A32: 5.6 อัตรารับชำระหนี้ถึงกำหนดเดือน มี.ค. 2569 ณ.31 มี.ค.2569 | C32: 2 | D32: P | F32: ร้อยละ | G32: 0.5 | H32: 85 | I32: 82 | J32: 84 | K32: 86 | L32: 88 | M32: 90 | N32: 93.47 | O32: =((Q32/5)*G32) -> 0.5 | Q32: =IF(N32=0,0,IF(N32>=M32,5,IF(N32>=L32,5-ABS(M32-N32)/(M32-L32),IF(N32>=K32,4-ABS(L32-N32)/(L32-K32),IF(N32>=J32,3-ABS(K32-N32)/(K32-J32),IF(N32>=I32,2-ABS(J32-N32)/(J32-I32),1)))))) -> 5
A33: 6. อัตรารับชำระหนี้ (สำรอง 1%) เดือน เม.ย. 68 - ม.ค. 69 ณ.สิ้นเดือนที่ 2 นับถัดจากเดือนที่ถึงกำหนดชำระ | D33: P | Q33: =IF(N33=0,0,IF(N33>=M33,5,IF(N33>=L33,5-ABS(M33-N33)/(M33-L33),IF(N33>=K33,4-ABS(L33-N33)/(L33-K33),IF(N33>=J33,3-ABS(K33-N33)/(K33-J33),IF(N33>=I33,2-ABS(J33-N33)/(J33-I33),1)))))) -> 0
A34: 6.1 อัตรารับชำระหนี้ถึงกำหนดเดือน ส.ค. 2568 ณ.31 ต.ค.2568 | C34: 2 | D34: P | F34: ร้อยละ | G34: 0.5 | H34: 90 | I34: 82 | J34: 84 | K34: 86 | L34: 88 | M34: 90 | N34: =ผลงานรวมทีม!E35 -> 100 | O34: =((Q34/5)*G34) -> 0.5 | Q34: =IF(N34=0,0,IF(N34>=M34,5,IF(N34>=L34,5-ABS(M34-N34)/(M34-L34),IF(N34>=K34,4-ABS(L34-N34)/(L34-K34),IF(N34>=J34,3-ABS(K34-N34)/(K34-J34),IF(N34>=I34,2-ABS(J34-N34)/(J34-I34),1)))))) -> 5
A35: 6.2 อัตรารับชำระหนี้ถึงกำหนดเดือน ก.ย. 2568 ณ.30 พ.ย.2568 | C35: 2 | D35: P | F35: ร้อยละ | G35: 0.5 | H35: 90 | I35: 82 | J35: 84 | K35: 86 | L35: 88 | M35: 90 | N35: =ผลงานรวมทีม!E36 -> 100 | O35: =((Q35/5)*G35) -> 0.5 | Q35: =IF(N35=0,0,IF(N35>=M35,5,IF(N35>=L35,5-ABS(M35-N35)/(M35-L35),IF(N35>=K35,4-ABS(L35-N35)/(L35-K35),IF(N35>=J35,3-ABS(K35-N35)/(K35-J35),IF(N35>=I35,2-ABS(J35-N35)/(J35-I35),1)))))) -> 5
A36: 6.3 อัตรารับชำระหนี้ถึงกำหนดเดือน ต.ค. 2568 ณ.31 ธ.ค.2568 | C36: 2 | D36: P | F36: ร้อยละ | G36: 0.5 | H36: 90 | I36: 82 | J36: 84 | K36: 86 | L36: 88 | M36: 90 | N36: =ผลงานรวมทีม!E37 -> 100 | O36: =((Q36/5)*G36) -> 0.5 | Q36: =IF(N36=0,0,IF(N36>=M36,5,IF(N36>=L36,5-ABS(M36-N36)/(M36-L36),IF(N36>=K36,4-ABS(L36-N36)/(L36-K36),IF(N36>=J36,3-ABS(K36-N36)/(K36-J36),IF(N36>=I36,2-ABS(J36-N36)/(J36-I36),1)))))) -> 5
A37: 6.4 อัตรารับชำระหนี้ถึงกำหนดเดือน พ.ย. 2568 ณ.31 ม.ค.2569 | C37: 2 | D37: P | F37: ร้อยละ | G37: 0.5 | H37: 90 | I37: 82 | J37: 84 | K37: 86 | L37: 88 | M37: 90 | N37: =ผลงานรวมทีม!E38 -> 100 | O37: =((Q37/5)*G37) -> 0.5 | Q37: =IF(N37=0,0,IF(N37>=M37,5,IF(N37>=L37,5-ABS(M37-N37)/(M37-L37),IF(N37>=K37,4-ABS(L37-N37)/(L37-K37),IF(N37>=J37,3-ABS(K37-N37)/(K37-J37),IF(N37>=I37,2-ABS(J37-N37)/(J37-I37),1)))))) -> 5
A38: 6.5 อัตรารับชำระหนี้ถึงกำหนดเดือน ธ.ค. 2568 ณ.28 ก.พ.2569 | C38: 2 | D38: P | F38: ร้อยละ | G38: 0.5 | H38: 90 | I38: 82 | J38: 84 | K38: 86 | L38: 88 | M38: 90 | N38: =ผลงานรวมทีม!E39 -> 99.79 | O38: =((Q38/5)*G38) -> 0.5 | Q38: =IF(N38=0,0,IF(N38>=M38,5,IF(N38>=L38,5-ABS(M38-N38)/(M38-L38),IF(N38>=K38,4-ABS(L38-N38)/(L38-K38),IF(N38>=J38,3-ABS(K38-N38)/(K38-J38),IF(N38>=I38,2-ABS(J38-N38)/(J38-I38),1)))))) -> 5
A39: 6.6 อัตรารับชำระหนี้ถึงกำหนดเดือน ม.ค. 2569 ณ.31 มี.ค.2569 | C39: 2 | D39: P | F39: ร้อยละ | G39: 0.5 | H39: 90 | I39: 82 | J39: 84 | K39: 86 | L39: 88 | M39: 90 | N39: =ผลงานรวมทีม!E40 -> 99.88 | O39: =((Q39/5)*G39) -> 0.5 | Q39: =IF(N39=0,0,IF(N39>=M39,5,IF(N39>=L39,5-ABS(M39-N39)/(M39-L39),IF(N39>=K39,4-ABS(L39-N39)/(L39-K39),IF(N39>=J39,3-ABS(K39-N39)/(K39-J39),IF(N39>=I39,2-ABS(J39-N39)/(J39-I39),1)))))) -> 5
A40: 7. อัตรารับชำระหนี้ เดือน ม.ค. 68 - ธ.ค. 68 ณ.สิ้นเดือนที่ 3 นับถัดจากเดือนที่ถึงกำหนดชำระ | Q40: =IF(N40=0,0,IF(N40>=M40,5,IF(N40>=L40,5-ABS(M40-N40)/(M40-L40),IF(N40>=K40,4-ABS(L40-N40)/(L40-K40),IF(N40>=J40,3-ABS(K40-N40)/(K40-J40),IF(N40>=I40,2-ABS(J40-N40)/(J40-I40),1)))))) -> 0
A41: 7.1 อัตรารับชำระหนี้ถึงกำหนดเดือน ก.ค. 2568 ณ.31 ต.ค.2568 | C41: 2 | D41: P | F41: ร้อยละ | G41: 0.5 | H41: 98.5 | I41: 94.5 | J41: 95.5 | K41: 96.5 | L41: 97.5 | M41: 98.5 | N41: =ผลงานรวมทีม!E48 -> 100 | O41: =((Q41/5)*G41) -> 0.5 | Q41: =IF(N41=0,0,IF(N41>=M41,5,IF(N41>=L41,5-ABS(M41-N41)/(M41-L41),IF(N41>=K41,4-ABS(L41-N41)/(L41-K41),IF(N41>=J41,3-ABS(K41-N41)/(K41-J41),IF(N41>=I41,2-ABS(J41-N41)/(J41-I41),1)))))) -> 5
A42: 7.2 อัตรารับชำระหนี้ถึงกำหนดเดือน ส.ค. 2568 ณ.30 พ.ย.2568 | C42: 2 | D42: P | F42: ร้อยละ | G42: 0.5 | H42: 98.5 | I42: 94.5 | J42: 95.5 | K42: 96.5 | L42: 97.5 | M42: 98.5 | N42: =ผลงานรวมทีม!E49 -> 100 | O42: =((Q42/5)*G42) -> 0.5 | Q42: =IF(N42=0,0,IF(N42>=M42,5,IF(N42>=L42,5-ABS(M42-N42)/(M42-L42),IF(N42>=K42,4-ABS(L42-N42)/(L42-K42),IF(N42>=J42,3-ABS(K42-N42)/(K42-J42),IF(N42>=I42,2-ABS(J42-N42)/(J42-I42),1)))))) -> 5
A43: 7.3 อัตรารับชำระหนี้ถึงกำหนดเดือน ก.ย. 2568 ณ.31 ธ.ค.2568 | C43: 2 | D43: P | F43: ร้อยละ | G43: 0.5 | H43: 98.5 | I43: 94.5 | J43: 95.5 | K43: 96.5 | L43: 97.5 | M43: 98.5 | N43: =ผลงานรวมทีม!E50 -> 99.95 | O43: =((Q43/5)*G43) -> 0.5 | Q43: =IF(N43=0,0,IF(N43>=M43,5,IF(N43>=L43,5-ABS(M43-N43)/(M43-L43),IF(N43>=K43,4-ABS(L43-N43)/(L43-K43),IF(N43>=J43,3-ABS(K43-N43)/(K43-J43),IF(N43>=I43,2-ABS(J43-N43)/(J43-I43),1)))))) -> 5
A44: 7.4 อัตรารับชำระหนี้ถึงกำหนดเดือน ต.ค. 2568 ณ.31 ม.ค.2569 | C44: 2 | D44: P | F44: ร้อยละ | G44: 0.5 | H44: 98.5 | I44: 94.5 | J44: 95.5 | K44: 96.5 | L44: 97.5 | M44: 98.5 | N44: =ผลงานรวมทีม!E51 -> 100 | O44: =((Q44/5)*G44) -> 0.5 | Q44: =IF(N44=0,0,IF(N44>=M44,5,IF(N44>=L44,5-ABS(M44-N44)/(M44-L44),IF(N44>=K44,4-ABS(L44-N44)/(L44-K44),IF(N44>=J44,3-ABS(K44-N44)/(K44-J44),IF(N44>=I44,2-ABS(J44-N44)/(J44-I44),1)))))) -> 5
...

Sheet พรพงศ์
A1: บันทึกข้อตกลงประเมินผลการปฏิบัติงานพนักงานรายคน ระดับ 1 - 9
A2: ปีบัญชี 2568
A4: ชื่อ - นามสกุล : | B4: นายพรพงศ์ สุวรรณวกุล | C4: รหัสพนักงาน : | D4: 6200379 | F4: พนักงาน | I4: ผู้บังคับบัญชาเบื้องต้น | L4: หัวหน้าส่วนงาน/Cluster
A5: ตำแหน่ง : | B5: พนักงานพัฒนาธุรกิจ 7 | C5: สังกัดกลุ่มงาน : | D5: หน่วยอำเภอ
A6: สาขา : | B6: ลำพญากลาง | C6: สนจ. : | D6: สระบุรี | F6: (นายพรพงศ์ สุวรรณวกุล) | I6: (นายภิชฌา ไทรทอง) | L6: (นางสาวใกล้รุ่ง หวังกั้นกลาง)
F7: ………………./………………./……………….. | I7: ………………./………………./……………….. | L7: ………………./………………./………………..
A10: หัวข้อประเมิน | F10: น้ำหนักคะแนน | G10: คะแนนประเมิน | I10: คะแนนประเมิน | K10: คะแนนเฉลี่ย | M10: หมายเหตุ
G11: ครั้งที่ 1 | I11: ครั้งที่ 2
A12: 1. ขีดความสามารถ (Competency) | F12: 20
A13: 2. การพัฒนาตนเอง (Self Development) | F13: 10 | G13: XX | I13: XX | K13: 10
A15: 3. ผลการดำเนินงาน (Performance) น้ำหนักคะแนน 70 คะแนน
A16: แผนงาน | C16: สนับสนุนยุทธศาสตร์ | D16: ประเภท | F16: ตัวชี้วัด | G16: น้ำหนัก | H16: เป้าหมาย | I16: ค่าคะแนน | N16: ผลงานจริง | O16: คะแนนที่ได้
C17: ยุทธศาสตร์ | D17: ทีม | E17: บุคคล | G17: คะแนน | I17: 1 | J17: 2 | K17: 3 | L17: 4* | M17: 5**
A18: งานสนับสนุนยุทธศาสตร์องค์กร / นโยบายสำคัญ | G18: XXX
A19: 1. รายได้FBI หมวด 1 –5 และสงเคราะห์ชีวิต | C19: 1 | D19: P | F19: ล้านบาท | G19: 2 | H19: 3.44 | I19: 2.06 | J19: 2.41 | K19: 2.75 | L19: 3.09 | M19: 3.44 | N19: =ผลงานรวมทีม!E58 -> 4.03 | O19: =((Q19/5)*G19) -> 2 | P19: ** | Q19: =IF(N19=0,0,IF(N19>=M19,5,IF(N19>=L19,5-ABS(M19-N19)/(M19-L19),IF(N19>=K19,4-ABS(L19-N19)/(L19-K19),IF(N19>=J19,3-ABS(K19-N19)/(K19-J19),IF(N19>=I19,2-ABS(J19-N19)/(J19-I19),1)))))) -> 5
A20: 2. โครงการสนับสนุนสินเชื่อ ESG ทั้งอุตสาหกรรมสีเขียวและสีน้ำเงิน | C20: 6 | D20: P | F20: ล้านบาท | G20: 4 | H20: 4.05 | I20: 2.92 | J20: 3.2 | K20: 3.48 | L20: 3.77 | M20: 4.05 | N20: =ผลงานรวมทีม!E9 -> 20 | O20: =((Q20/5)*G20) -> 4 | Q20: =IF(N20=0,0,IF(N20>=M20,5,IF(N20>=L20,5-ABS(M20-N20)/(M20-L20),IF(N20>=K20,4-ABS(L20-N20)/(L20-K20),IF(N20>=J20,3-ABS(K20-N20)/(K20-J20),IF(N20>=I20,2-ABS(J20-N20)/(J20-I20),1)))))) -> 5
A21: 3. โครงการเพิ่มฐานลูกค้าสินเชื่อเกษตรกรกลุ่มใหม่ | C21: 2 | D21: P | F21: ราย | G21: 3 | H21: 47 | I21: 35 | J21: 38 | K21: 41 | L21: 45 | M21: 47 | N21: =ผลงานรวมทีม!E10 -> 57 | O21: =((Q21/5)*G21) -> 3 | Q21: =IF(N21=0,0,IF(N21>=M21,5,IF(N21>=L21,5-ABS(M21-N21)/(M21-L21),IF(N21>=K21,4-ABS(L21-N21)/(L21-K21),IF(N21>=J21,3-ABS(K21-N21)/(K21-J21),IF(N21>=I21,2-ABS(J21-N21)/(J21-I21),1)))))) -> 5
A22: 4. การอนุมัติสินเชื่อใหม่ลูกค้าบุคคลธรรมดาและเกษตรกร (S2) | C22: 2 | D22: P | F22: ราย | G22: 3 | H22: 280 | I22: 193 | J22: 204 | K22: 248 | L22: 276 | M22: 280 | N22: =ผลงานรวมทีม!E11 -> 331 | O22: =((Q22/5)*G22) -> 3 | Q22: =IF(N22=0,0,IF(N22>=M22,5,IF(N22>=L22,5-ABS(M22-N22)/(M22-L22),IF(N22>=K22,4-ABS(L22-N22)/(L22-K22),IF(N22>=J22,3-ABS(K22-N22)/(K22-J22),IF(N22>=I22,2-ABS(J22-N22)/(J22-I22),1)))))) -> 5
A23: 5. โครงการพัฒนาทายาททดแทน | C23: 2 | D23: P | F23: ราย | G23: 3 | H23: 2 | I23: 0 | J23: 0 | K23: 0 | L23: 0 | M23: 2 | N23: =ผลงานรวมทีม!E12 -> 3 | O23: =((Q23/5)*G23) -> 3 | Q23: =IF(N23=0,0,IF(N23>=M23,5,IF(N23>=L23,5-ABS(M23-N23)/(M23-L23),IF(N23>=K23,4-ABS(L23-N23)/(L23-K23),IF(N23>=J23,3-ABS(K23-N23)/(K23-J23),IF(N23>=I23,2-ABS(J23-N23)/(J23-I23),1)))))) -> 5
A24: 6. Loan Growth | Q24: =IF(N24=0,0,IF(N24>=M24,5,IF(N24>=L24,5-ABS(M24-N24)/(M24-L24),IF(N24>=K24,4-ABS(L24-N24)/(L24-K24),IF(N24>=J24,3-ABS(K24-N24)/(K24-J24),IF(N24>=I24,2-ABS(J24-N24)/(J24-I24),1)))))) -> 0
A25: 6.1 การเติบโตสินเชื่อกลุ่มผลิตภัณฑ์ Secure Loan | C25: 2 | D25: P | F25: ล้านบาท | G25: 4 | H25: 8.73 | I25: 6.98 | J25: 7.42 | K25: 7.86 | L25: 8.29 | M25: 8.73 | N25: =ผลงานรวมทีม!E14 -> 10.28 | O25: =((Q25/5)*G25) -> 4 | Q25: =IF(N25=0,0,IF(N25>=M25,5,IF(N25>=L25,5-ABS(M25-N25)/(M25-L25),IF(N25>=K25,4-ABS(L25-N25)/(L25-K25),IF(N25>=J25,3-ABS(K25-N25)/(K25-J25),IF(N25>=I25,2-ABS(J25-N25)/(J25-I25),1)))))) -> 5
A26: 6.2 การเติบโตสินเชื่อ | C26: 2 | D26: P | F26: ล้านบาท | G26: 4 | H26: 7.17 | I26: 5.74 | J26: 6.09 | K26: 6.45 | L26: 6.85 | M26: 7.17 | N26: =ผลงานรวมทีม!E15 -> -204.38 | O26: =((Q26/5)*G26) -> 0.8 | Q26: =IF(N26=0,0,IF(N26>=M26,5,IF(N26>=L26,5-ABS(M26-N26)/(M26-L26),IF(N26>=K26,4-ABS(L26-N26)/(L26-K26),IF(N26>=J26,3-ABS(K26-N26)/(K26-J26),IF(N26>=I26,2-ABS(J26-N26)/(J26-I26),1)))))) -> 1
A27: งานตามภารกิจ (Job / Routine) | Q27: =IF(N27=0,0,IF(N27>=M27,5,IF(N27>=L27,5-ABS(M27-N27)/(M27-L27),IF(N27>=K27,4-ABS(L27-N27)/(L27-K27),IF(N27>=J27,3-ABS(K27-N27)/(K27-J27),IF(N27>=I27,2-ABS(J27-N27)/(J27-I27),1)))))) -> 0
A28: 7. อัตรารับชำระหนี้ เดือน เม.ย. 68 - มี.ค. 69 ณ.สิ้นเดือนที่ถึงกำหนดชำระ | Q28: =IF(N28=0,0,IF(N28>=M28,5,IF(N28>=L28,5-ABS(M28-N28)/(M28-L28),IF(N28>=K28,4-ABS(L28-N28)/(L28-K28),IF(N28>=J28,3-ABS(K28-N28)/(K28-J28),IF(N28>=I28,2-ABS(J28-N28)/(J28-I28),1)))))) -> 0
A29: 7.1อัตรารับชำระหนี้ถึงกำหนดเดือน เม.ย. 2568 ณ.30 เม.ย.2568 | C29: 2 | D29: P | F29: ร้อยละ | G29: 0.5 | H29: 85 | I29: 77 | J29: 79 | K29: 81 | L29: 83 | M29: 85 | N29: =ผลงานรวมทีม!E18 -> 93.04 | O29: =((Q29/5)*G29) -> 0.5 | Q29: =IF(N29=0,0,IF(N29>=M29,5,IF(N29>=L29,5-ABS(M29-N29)/(M29-L29),IF(N29>=K29,4-ABS(L29-N29)/(L29-K29),IF(N29>=J29,3-ABS(K29-N29)/(K29-J29),IF(N29>=I29,2-ABS(J29-N29)/(J29-I29),1)))))) -> 5
A30: 7.2อัตรารับชำระหนี้ถึงกำหนดเดือน พ.ค. 2568 ณ.31 พ.ค.2568 | C30: 2 | D30: P | F30: ร้อยละ | G30: 0.5 | H30: 85 | I30: 77 | J30: 79 | K30: 81 | L30: 83 | M30: 85 | N30: =ผลงานรวมทีม!E19 -> 93.22 | O30: =((Q30/5)*G30) -> 0.5 | Q30: =IF(N30=0,0,IF(N30>=M30,5,IF(N30>=L30,5-ABS(M30-N30)/(M30-L30),IF(N30>=K30,4-ABS(L30-N30)/(L30-K30),IF(N30>=J30,3-ABS(K30-N30)/(K30-J30),IF(N30>=I30,2-ABS(J30-N30)/(J30-I30),1)))))) -> 5
A31: 7.3อัตรารับชำระหนี้ถึงกำหนดเดือน มิ.ย. 2568 ณ.30 มิ.ย.2568 | C31: 2 | D31: P | F31: ร้อยละ | G31: 0.5 | H31: 85 | I31: 77 | J31: 79 | K31: 81 | L31: 83 | M31: 85 | N31: =ผลงานรวมทีม!E20 -> 83.1 | O31: =((Q31/5)*G31) -> 0.405 | Q31: =IF(N31=0,0,IF(N31>=M31,5,IF(N31>=L31,5-ABS(M31-N31)/(M31-L31),IF(N31>=K31,4-ABS(L31-N31)/(L31-K31),IF(N31>=J31,3-ABS(K31-N31)/(K31-J31),IF(N31>=I31,2-ABS(J31-N31)/(J31-I31),1)))))) -> 4.05
A32: 7.4อัตรารับชำระหนี้ถึงกำหนดเดือน ก.ค. 2568 ณ.31 ก.ค.2568 | C32: 2 | D32: P | F32: ร้อยละ | G32: 0.5 | H32: 85 | I32: 77 | J32: 79 | K32: 81 | L32: 83 | M32: 85 | N32: =ผลงานรวมทีม!E21 -> 93.54 | O32: =((Q32/5)*G32) -> 0.5 | Q32: =IF(N32=0,0,IF(N32>=M32,5,IF(N32>=L32,5-ABS(M32-N32)/(M32-L32),IF(N32>=K32,4-ABS(L32-N32)/(L32-K32),IF(N32>=J32,3-ABS(K32-N32)/(K32-J32),IF(N32>=I32,2-ABS(J32-N32)/(J32-I32),1)))))) -> 5
A33: 7.5อัตรารับชำระหนี้ถึงกำหนดเดือน ส.ค. 2568 ณ.31 ส.ค.2568 | C33: 2 | D33: P | F33: ร้อยละ | G33: 0.5 | H33: 85 | I33: 77 | J33: 79 | K33: 81 | L33: 83 | M33: 85 | N33: =ผลงานรวมทีม!E22 -> 93.89 | O33: =((Q33/5)*G33) -> 0.5 | Q33: =IF(N33=0,0,IF(N33>=M33,5,IF(N33>=L33,5-ABS(M33-N33)/(M33-L33),IF(N33>=K33,4-ABS(L33-N33)/(L33-K33),IF(N33>=J33,3-ABS(K33-N33)/(K33-J33),IF(N33>=I33,2-ABS(J33-N33)/(J33-I33),1)))))) -> 5
A34: 7.6อัตรารับชำระหนี้ถึงกำหนดเดือน ก.ย. 2568 ณ.30 ก.ย.2568 | C34: 2 | D34: P | F34: ร้อยละ | G34: 0.5 | H34: 85 | I34: 77 | J34: 79 | K34: 81 | L34: 83 | M34: 85 | N34: =ผลงานรวมทีม!E23 -> 99.51 | O34: =((Q34/5)*G34) -> 0.5 | Q34: =IF(N34=0,0,IF(N34>=M34,5,IF(N34>=L34,5-ABS(M34-N34)/(M34-L34),IF(N34>=K34,4-ABS(L34-N34)/(L34-K34),IF(N34>=J34,3-ABS(K34-N34)/(K34-J34),IF(N34>=I34,2-ABS(J34-N34)/(J34-I34),1)))))) -> 5
A35: 7.7อัตรารับชำระหนี้ถึงกำหนดเดือน ต.ค. 2568 ณ.31 ต.ค.2568 | C35: 2 | D35: P | F35: ร้อยละ | G35: 0.5 | H35: 85 | I35: 77 | J35: 79 | K35: 81 | L35: 83 | M35: 85 | N35: =ผลงานรวมทีม!E24 -> 97.86 | O35: =((Q35/5)*G35) -> 0.5 | Q35: =IF(N35=0,0,IF(N35>=M35,5,IF(N35>=L35,5-ABS(M35-N35)/(M35-L35),IF(N35>=K35,4-ABS(L35-N35)/(L35-K35),IF(N35>=J35,3-ABS(K35-N35)/(K35-J35),IF(N35>=I35,2-ABS(J35-N35)/(J35-I35),1)))))) -> 5
A36: 7.8อัตรารับชำระหนี้ถึงกำหนดเดือน พ.ย. 2568 ณ.30 พ.ย.2568 | C36: 2 | D36: P | F36: ร้อยละ | G36: 0.5 | H36: 85 | I36: 77 | J36: 79 | K36: 81 | L36: 83 | M36: 85 | N36: =ผลงานรวมทีม!E25 -> 97.99 | O36: =((Q36/5)*G36) -> 0.5 | Q36: =IF(N36=0,0,IF(N36>=M36,5,IF(N36>=L36,5-ABS(M36-N36)/(M36-L36),IF(N36>=K36,4-ABS(L36-N36)/(L36-K36),IF(N36>=J36,3-ABS(K36-N36)/(K36-J36),IF(N36>=I36,2-ABS(J36-N36)/(J36-I36),1)))))) -> 5
A37: 7.9อัตรารับชำระหนี้ถึงกำหนดเดือน ธ.ค. 2568 ณ.31 ธ.ค.2568 | C37: 2 | D37: P | F37: ร้อยละ | G37: 0.5 | H37: 85 | I37: 77 | J37: 79 | K37: 81 | L37: 83 | M37: 85 | N37: =ผลงานรวมทีม!E26 -> 86.99 | O37: =((Q37/5)*G37) -> 0.5 | Q37: =IF(N37=0,0,IF(N37>=M37,5,IF(N37>=L37,5-ABS(M37-N37)/(M37-L37),IF(N37>=K37,4-ABS(L37-N37)/(L37-K37),IF(N37>=J37,3-ABS(K37-N37)/(K37-J37),IF(N37>=I37,2-ABS(J37-N37)/(J37-I37),1)))))) -> 5
A38: 7.10อัตรารับชำระหนี้ถึงกำหนดเดือน ม.ค. 2569 ณ.31 ม.ค.2569 | C38: 2 | D38: P | F38: ร้อยละ | G38: 0.5 | H38: 85 | I38: 77 | J38: 79 | K38: 81 | L38: 83 | M38: 85 | N38: =ผลงานรวมทีม!E27 -> 97.53 | O38: =((Q38/5)*G38) -> 0.5 | Q38: =IF(N38=0,0,IF(N38>=M38,5,IF(N38>=L38,5-ABS(M38-N38)/(M38-L38),IF(N38>=K38,4-ABS(L38-N38)/(L38-K38),IF(N38>=J38,3-ABS(K38-N38)/(K38-J38),IF(N38>=I38,2-ABS(J38-N38)/(J38-I38),1)))))) -> 5
A39: 7.11อัตรารับชำระหนี้ถึงกำหนดเดือน ก.พ. 2569 ณ.28 ก.พ.2569 | C39: 2 | D39: P | F39: ร้อยละ | G39: 0.5 | H39: 85 | I39: 77 | J39: 79 | K39: 81 | L39: 83 | M39: 85 | N39: =ผลงานรวมทีม!E28 -> 98.13 | O39: =((Q39/5)*G39) -> 0.5 | Q39: =IF(N39=0,0,IF(N39>=M39,5,IF(N39>=L39,5-ABS(M39-N39)/(M39-L39),IF(N39>=K39,4-ABS(L39-N39)/(L39-K39),IF(N39>=J39,3-ABS(K39-N39)/(K39-J39),IF(N39>=I39,2-ABS(J39-N39)/(J39-I39),1)))))) -> 5
A40: 7.12อัตรารับชำระหนี้ถึงกำหนดเดือน มี.ค. 2569 ณ.31 มี.ค.2569 | C40: 2 | D40: P | F40: ร้อยละ | G40: 0.5 | H40: 90 | I40: 82 | J40: 84 | K40: 86 | L40: 88 | M40: 90 | N40: =ผลงานรวมทีม!E29 -> 93.47 | O40: =((Q40/5)*G40) -> 0.5 | Q40: =IF(N40=0,0,IF(N40>=M40,5,IF(N40>=L40,5-ABS(M40-N40)/(M40-L40),IF(N40>=K40,4-ABS(L40-N40)/(L40-K40),IF(N40>=J40,3-ABS(K40-N40)/(K40-J40),IF(N40>=I40,2-ABS(J40-N40)/(J40-I40),1)))))) -> 5
A41: 8. อัตรารับชำระหนี้ (สำรอง 1%) เดือน เม.ย. 68 - ม.ค. 69 ณ.สิ้นเดือนที่ 2 นับถัดจากเดือนที่ถึงกำหนดชำระ | Q41: =IF(N41=0,0,IF(N41>=M41,5,IF(N41>=L41,5-ABS(M41-N41)/(M41-L41),IF(N41>=K41,4-ABS(L41-N41)/(L41-K41),IF(N41>=J41,3-ABS(K41-N41)/(K41-J41),IF(N41>=I41,2-ABS(J41-N41)/(J41-I41),1)))))) -> 0
A42: 8.1อัตรารับชำระหนี้ถึงกำหนด(สำรอง 1%) เดือน เม.ย. 2568 ณ.30 มิ.ย.2568 | C42: 2 | E42: P | F42: ร้อยละ | G42: 0.5 | H42: 90 | I42: 82 | J42: 84 | K42: 86 | L42: 88 | M42: 90 | N42: =ผลงานรายเขต!F31 -> 93.04 | O42: =((Q42/5)*G42) -> 0.5 | Q42: =IF(N42=0,0,IF(N42>=M42,5,IF(N42>=L42,5-ABS(M42-N42)/(M42-L42),IF(N42>=K42,4-ABS(L42-N42)/(L42-K42),IF(N42>=J42,3-ABS(K42-N42)/(K42-J42),IF(N42>=I42,2-ABS(J42-N42)/(J42-I42),1)))))) -> 5
A43: 8.2อัตรารับชำระหนี้ถึงกำหนด(สำรอง 1%) พ.ค. 2568 ณ.31 ก.ค.2568 | C43: 2 | E43: P | F43: ร้อยละ | G43: 0.5 | H43: 90 | I43: 82 | J43: 84 | K43: 86 | L43: 88 | M43: 90 | N43: =ผลงานรายเขต!F32 -> 93.22 | O43: =((Q43/5)*G43) -> 0.5 | Q43: =IF(N43=0,0,IF(N43>=M43,5,IF(N43>=L43,5-ABS(M43-N43)/(M43-L43),IF(N43>=K43,4-ABS(L43-N43)/(L43-K43),IF(N43>=J43,3-ABS(K43-N43)/(K43-J43),IF(N43>=I43,2-ABS(J43-N43)/(J43-I43),1)))))) -> 5
A44: 8.3อัตรารับชำระหนี้ถึงกำหนด(สำรอง 1%) มิ.ย. 2568 ณ.31 ส.ค.2568 | C44: 2 | E44: P | F44: ร้อยละ | G44: 0.5 | H44: 90 | I44: 82 | J44: 84 | K44: 86 | L44: 88 | M44: 90 | N44: =ผลงานรายเขต!F33 -> 83.1 | O44: =((Q44/5)*G44) -> 0.155 | Q44: =IF(N44=0,0,IF(N44>=M44,5,IF(N44>=L44,5-ABS(M44-N44)/(M44-L44),IF(N44>=K44,4-ABS(L44-N44)/(L44-K44),IF(N44>=J44,3-ABS(K44-N44)/(K44-J44),IF(N44>=I44,2-ABS(J44-N44)/(J44-I44),1)))))) -> 1.55
...

Sheet พิราวรรณ
A1: บันทึกข้อตกลงประเมินผลการปฏิบัติงานพนักงานรายคน ระดับ 1 - 9
A2: ปีบัญชี 2568
A4: ชื่อ - นามสกุล : | B4: นางพิราวรรณ สุวรรณนิตย์กุล | C4: รหัสพนักงาน : | D4: 6400134 | F4: พนักงาน | I4: ผู้บังคับบัญชาเบื้องต้น | L4: หัวหน้าส่วนงาน/Cluster
A5: ตำแหน่ง : | B5: พนักงานพัฒนาธุรกิจ 6 | C5: สังกัดกลุ่มงาน : | D5: หน่วยอำเภอ
A6: สาขา : | B6: ลำพญากลาง | C6: สนจ. : | D6: สระบุรี | F6: (นางพิราวรรณ สุวรรณนิตย์กุล) | I6: (นายภิชฌา ไทรทอง) | L6: (นางสาวใกล้รุ่ง หวังกั้นกลาง)
F7: ………………./………………./……………….. | I7: ………………./………………./……………….. | L7: ………………./………………./………………..
A10: หัวข้อประเมิน | F10: น้ำหนักคะแนน | G10: คะแนนประเมิน | I10: คะแนนประเมิน | K10: คะแนนเฉลี่ย | M10: หมายเหตุ
G11: ครั้งที่ 1 | I11: ครั้งที่ 2
A12: 1. ขีดความสามารถ (Competency) | F12: 20
A13: 2. การพัฒนาตนเอง (Self Development) | F13: 10 | G13: XX | I13: XX | K13: 10
A15: 3. ผลการดำเนินงาน (Performance) น้ำหนักคะแนน 70 คะแนน
A16: แผนงาน | C16: สนับสนุนยุทธศาสตร์ | D16: ประเภท | F16: ตัวชี้วัด | G16: น้ำหนัก | H16: เป้าหมาย | I16: ค่าคะแนน | N16: ผลงานจริง | O16: คะแนนที่ได้
C17: ยุทธศาสตร์ | D17: ทีม | E17: บุคคล | G17: คะแนน | I17: 1 | J17: 2 | K17: 3 | L17: 4* | M17: 5**
A18: งานสนับสนุนยุทธศาสตร์องค์กร / นโยบายสำคัญ | G18: XXX
A19: 1. รายได้FBI หมวด 1 –5 และสงเคราะห์ชีวิต | C19: 1 | D19: P | F19: ล้านบาท | G19: 2 | H19: 3.44 | I19: 2.06 | J19: 2.41 | K19: 2.75 | L19: 3.09 | M19: 3.44 | N19: =ผลงานรวมทีม!E58 -> 4.03 | O19: =((Q19/5)*G19) -> 2 | P19: ** | Q19: =IF(N19=0,0,IF(N19>=M19,5,IF(N19>=L19,5-ABS(M19-N19)/(M19-L19),IF(N19>=K19,4-ABS(L19-N19)/(L19-K19),IF(N19>=J19,3-ABS(K19-N19)/(K19-J19),IF(N19>=I19,2-ABS(J19-N19)/(J19-I19),1)))))) -> 5
A20: 2. โครงการสนับสนุนสินเชื่อ ESG ทั้งอุตสาหกรรมสีเขียวและสีน้ำเงิน | C20: 6 | D20: P | F20: ล้านบาท | G20: 4 | H20: 4.05 | I20: 2.92 | J20: 3.2 | K20: 3.48 | L20: 3.77 | M20: 4.05 | N20: =ผลงานรวมทีม!E9 -> 20 | O20: =((Q20/5)*G20) -> 4 | Q20: =IF(N20=0,0,IF(N20>=M20,5,IF(N20>=L20,5-ABS(M20-N20)/(M20-L20),IF(N20>=K20,4-ABS(L20-N20)/(L20-K20),IF(N20>=J20,3-ABS(K20-N20)/(K20-J20),IF(N20>=I20,2-ABS(J20-N20)/(J20-I20),1)))))) -> 5
A21: 3. โครงการเพิ่มฐานลูกค้าสินเชื่อเกษตรกรกลุ่มใหม่ | C21: 2 | D21: P | F21: ราย | G21: 3 | H21: 47 | I21: 35 | J21: 38 | K21: 41 | L21: 45 | M21: 47 | N21: =ผลงานรวมทีม!E10 -> 57 | O21: =((Q21/5)*G21) -> 3 | Q21: =IF(N21=0,0,IF(N21>=M21,5,IF(N21>=L21,5-ABS(M21-N21)/(M21-L21),IF(N21>=K21,4-ABS(L21-N21)/(L21-K21),IF(N21>=J21,3-ABS(K21-N21)/(K21-J21),IF(N21>=I21,2-ABS(J21-N21)/(J21-I21),1)))))) -> 5
A22: 4. การอนุมัติสินเชื่อใหม่ลูกค้าบุคคลธรรมดาและเกษตรกร (S2) | C22: 2 | D22: P | F22: ราย | G22: 3 | H22: 280 | I22: 193 | J22: 204 | K22: 248 | L22: 276 | M22: 280 | N22: =ผลงานรวมทีม!E11 -> 331 | O22: =((Q22/5)*G22) -> 3 | Q22: =IF(N22=0,0,IF(N22>=M22,5,IF(N22>=L22,5-ABS(M22-N22)/(M22-L22),IF(N22>=K22,4-ABS(L22-N22)/(L22-K22),IF(N22>=J22,3-ABS(K22-N22)/(K22-J22),IF(N22>=I22,2-ABS(J22-N22)/(J22-I22),1)))))) -> 5
A23: 5. โครงการพัฒนาทายาททดแทน | C23: 2 | D23: P | F23: ราย | G23: 3 | H23: 2 | I23: 0 | J23: 0 | K23: 0 | L23: 0 | M23: 2 | N23: =ผลงานรวมทีม!E12 -> 3 | O23: =((Q23/5)*G23) -> 3 | Q23: =IF(N23=0,0,IF(N23>=M23,5,IF(N23>=L23,5-ABS(M23-N23)/(M23-L23),IF(N23>=K23,4-ABS(L23-N23)/(L23-K23),IF(N23>=J23,3-ABS(K23-N23)/(K23-J23),IF(N23>=I23,2-ABS(J23-N23)/(J23-I23),1)))))) -> 5
A24: 6. Loan Growth | Q24: =IF(N24=0,0,IF(N24>=M24,5,IF(N24>=L24,5-ABS(M24-N24)/(M24-L24),IF(N24>=K24,4-ABS(L24-N24)/(L24-K24),IF(N24>=J24,3-ABS(K24-N24)/(K24-J24),IF(N24>=I24,2-ABS(J24-N24)/(J24-I24),1)))))) -> 0
A25: 6.1 การเติบโตสินเชื่อกลุ่มผลิตภัณฑ์ Secure Loan | C25: 2 | D25: P | F25: ล้านบาท | G25: 4 | H25: 8.73 | I25: 6.98 | J25: 7.42 | K25: 7.86 | L25: 8.29 | M25: 8.73 | N25: =ผลงานรวมทีม!E14 -> 10.28 | O25: =((Q25/5)*G25) -> 4 | Q25: =IF(N25=0,0,IF(N25>=M25,5,IF(N25>=L25,5-ABS(M25-N25)/(M25-L25),IF(N25>=K25,4-ABS(L25-N25)/(L25-K25),IF(N25>=J25,3-ABS(K25-N25)/(K25-J25),IF(N25>=I25,2-ABS(J25-N25)/(J25-I25),1)))))) -> 5
A26: 6.2 การเติบโตสินเชื่อ | C26: 2 | D26: P | F26: ล้านบาท | G26: 4 | H26: 7.17 | I26: 5.74 | J26: 6.09 | K26: 6.45 | L26: 6.85 | M26: 7.17 | N26: =ผลงานรวมทีม!E15 -> -204.38 | O26: =((Q26/5)*G26) -> 0.8 | Q26: =IF(N26=0,0,IF(N26>=M26,5,IF(N26>=L26,5-ABS(M26-N26)/(M26-L26),IF(N26>=K26,4-ABS(L26-N26)/(L26-K26),IF(N26>=J26,3-ABS(K26-N26)/(K26-J26),IF(N26>=I26,2-ABS(J26-N26)/(J26-I26),1)))))) -> 1
A27: งานตามภารกิจ (Job / Routine) | Q27: =IF(N27=0,0,IF(N27>=M27,5,IF(N27>=L27,5-ABS(M27-N27)/(M27-L27),IF(N27>=K27,4-ABS(L27-N27)/(L27-K27),IF(N27>=J27,3-ABS(K27-N27)/(K27-J27),IF(N27>=I27,2-ABS(J27-N27)/(J27-I27),1)))))) -> 0
A28: 7. อัตรารับชำระหนี้ เดือน เม.ย. 68 - มี.ค. 69 ณ.สิ้นเดือนที่ถึงกำหนดชำระ | Q28: =IF(N28=0,0,IF(N28>=M28,5,IF(N28>=L28,5-ABS(M28-N28)/(M28-L28),IF(N28>=K28,4-ABS(L28-N28)/(L28-K28),IF(N28>=J28,3-ABS(K28-N28)/(K28-J28),IF(N28>=I28,2-ABS(J28-N28)/(J28-I28),1)))))) -> 0
A29: 7.1อัตรารับชำระหนี้ถึงกำหนดเดือน เม.ย. 2568 ณ.30 เม.ย.2568 | C29: 2 | D29: P | F29: ร้อยละ | G29: 0.5 | H29: 85 | I29: 77 | J29: 79 | K29: 81 | L29: 83 | M29: 85 | N29: =ผลงานรวมทีม!E18 -> 93.04 | O29: =((Q29/5)*G29) -> 0.5 | Q29: =IF(N29=0,0,IF(N29>=M29,5,IF(N29>=L29,5-ABS(M29-N29)/(M29-L29),IF(N29>=K29,4-ABS(L29-N29)/(L29-K29),IF(N29>=J29,3-ABS(K29-N29)/(K29-J29),IF(N29>=I29,2-ABS(J29-N29)/(J29-I29),1)))))) -> 5
A30: 7.2อัตรารับชำระหนี้ถึงกำหนดเดือน พ.ค. 2568 ณ.31 พ.ค.2568 | C30: 2 | D30: P | F30: ร้อยละ | G30: 0.5 | H30: 85 | I30: 77 | J30: 79 | K30: 81 | L30: 83 | M30: 85 | N30: =ผลงานรวมทีม!E19 -> 93.22 | O30: =((Q30/5)*G30) -> 0.5 | Q30: =IF(N30=0,0,IF(N30>=M30,5,IF(N30>=L30,5-ABS(M30-N30)/(M30-L30),IF(N30>=K30,4-ABS(L30-N30)/(L30-K30),IF(N30>=J30,3-ABS(K30-N30)/(K30-J30),IF(N30>=I30,2-ABS(J30-N30)/(J30-I30),1)))))) -> 5
A31: 7.3อัตรารับชำระหนี้ถึงกำหนดเดือน มิ.ย. 2568 ณ.30 มิ.ย.2568 | C31: 2 | D31: P | F31: ร้อยละ | G31: 0.5 | H31: 85 | I31: 77 | J31: 79 | K31: 81 | L31: 83 | M31: 85 | N31: =ผลงานรวมทีม!E20 -> 83.1 | O31: =((Q31/5)*G31) -> 0.405 | Q31: =IF(N31=0,0,IF(N31>=M31,5,IF(N31>=L31,5-ABS(M31-N31)/(M31-L31),IF(N31>=K31,4-ABS(L31-N31)/(L31-K31),IF(N31>=J31,3-ABS(K31-N31)/(K31-J31),IF(N31>=I31,2-ABS(J31-N31)/(J31-I31),1)))))) -> 4.05
A32: 7.4อัตรารับชำระหนี้ถึงกำหนดเดือน ก.ค. 2568 ณ.31 ก.ค.2568 | C32: 2 | D32: P | F32: ร้อยละ | G32: 0.5 | H32: 85 | I32: 77 | J32: 79 | K32: 81 | L32: 83 | M32: 85 | N32: =ผลงานรวมทีม!E21 -> 93.54 | O32: =((Q32/5)*G32) -> 0.5 | Q32: =IF(N32=0,0,IF(N32>=M32,5,IF(N32>=L32,5-ABS(M32-N32)/(M32-L32),IF(N32>=K32,4-ABS(L32-N32)/(L32-K32),IF(N32>=J32,3-ABS(K32-N32)/(K32-J32),IF(N32>=I32,2-ABS(J32-N32)/(J32-I32),1)))))) -> 5
A33: 7.5อัตรารับชำระหนี้ถึงกำหนดเดือน ส.ค. 2568 ณ.31 ส.ค.2568 | C33: 2 | D33: P | F33: ร้อยละ | G33: 0.5 | H33: 85 | I33: 77 | J33: 79 | K33: 81 | L33: 83 | M33: 85 | N33: =ผลงานรวมทีม!E22 -> 93.89 | O33: =((Q33/5)*G33) -> 0.5 | Q33: =IF(N33=0,0,IF(N33>=M33,5,IF(N33>=L33,5-ABS(M33-N33)/(M33-L33),IF(N33>=K33,4-ABS(L33-N33)/(L33-K33),IF(N33>=J33,3-ABS(K33-N33)/(K33-J33),IF(N33>=I33,2-ABS(J33-N33)/(J33-I33),1)))))) -> 5
A34: 7.6อัตรารับชำระหนี้ถึงกำหนดเดือน ก.ย. 2568 ณ.30 ก.ย.2568 | C34: 2 | D34: P | F34: ร้อยละ | G34: 0.5 | H34: 85 | I34: 77 | J34: 79 | K34: 81 | L34: 83 | M34: 85 | N34: =ผลงานรวมทีม!E23 -> 99.51 | O34: =((Q34/5)*G34) -> 0.5 | Q34: =IF(N34=0,0,IF(N34>=M34,5,IF(N34>=L34,5-ABS(M34-N34)/(M34-L34),IF(N34>=K34,4-ABS(L34-N34)/(L34-K34),IF(N34>=J34,3-ABS(K34-N34)/(K34-J34),IF(N34>=I34,2-ABS(J34-N34)/(J34-I34),1)))))) -> 5
A35: 7.7อัตรารับชำระหนี้ถึงกำหนดเดือน ต.ค. 2568 ณ.31 ต.ค.2568 | C35: 2 | D35: P | F35: ร้อยละ | G35: 0.5 | H35: 85 | I35: 77 | J35: 79 | K35: 81 | L35: 83 | M35: 85 | N35: =ผลงานรวมทีม!E24 -> 97.86 | O35: =((Q35/5)*G35) -> 0.5 | Q35: =IF(N35=0,0,IF(N35>=M35,5,IF(N35>=L35,5-ABS(M35-N35)/(M35-L35),IF(N35>=K35,4-ABS(L35-N35)/(L35-K35),IF(N35>=J35,3-ABS(K35-N35)/(K35-J35),IF(N35>=I35,2-ABS(J35-N35)/(J35-I35),1)))))) -> 5
A36: 7.8อัตรารับชำระหนี้ถึงกำหนดเดือน พ.ย. 2568 ณ.30 พ.ย.2568 | C36: 2 | D36: P | F36: ร้อยละ | G36: 0.5 | H36: 85 | I36: 77 | J36: 79 | K36: 81 | L36: 83 | M36: 85 | N36: =ผลงานรวมทีม!E25 -> 97.99 | O36: =((Q36/5)*G36) -> 0.5 | Q36: =IF(N36=0,0,IF(N36>=M36,5,IF(N36>=L36,5-ABS(M36-N36)/(M36-L36),IF(N36>=K36,4-ABS(L36-N36)/(L36-K36),IF(N36>=J36,3-ABS(K36-N36)/(K36-J36),IF(N36>=I36,2-ABS(J36-N36)/(J36-I36),1)))))) -> 5
A37: 7.9อัตรารับชำระหนี้ถึงกำหนดเดือน ธ.ค. 2568 ณ.31 ธ.ค.2568 | C37: 2 | D37: P | F37: ร้อยละ | G37: 0.5 | H37: 85 | I37: 77 | J37: 79 | K37: 81 | L37: 83 | M37: 85 | N37: =ผลงานรวมทีม!E26 -> 86.99 | O37: =((Q37/5)*G37) -> 0.5 | Q37: =IF(N37=0,0,IF(N37>=M37,5,IF(N37>=L37,5-ABS(M37-N37)/(M37-L37),IF(N37>=K37,4-ABS(L37-N37)/(L37-K37),IF(N37>=J37,3-ABS(K37-N37)/(K37-J37),IF(N37>=I37,2-ABS(J37-N37)/(J37-I37),1)))))) -> 5
A38: 7.10อัตรารับชำระหนี้ถึงกำหนดเดือน ม.ค. 2569 ณ.31 ม.ค.2569 | C38: 2 | D38: P | F38: ร้อยละ | G38: 0.5 | H38: 85 | I38: 77 | J38: 79 | K38: 81 | L38: 83 | M38: 85 | N38: =ผลงานรวมทีม!E27 -> 97.53 | O38: =((Q38/5)*G38) -> 0.5 | Q38: =IF(N38=0,0,IF(N38>=M38,5,IF(N38>=L38,5-ABS(M38-N38)/(M38-L38),IF(N38>=K38,4-ABS(L38-N38)/(L38-K38),IF(N38>=J38,3-ABS(K38-N38)/(K38-J38),IF(N38>=I38,2-ABS(J38-N38)/(J38-I38),1)))))) -> 5
A39: 7.11อัตรารับชำระหนี้ถึงกำหนดเดือน ก.พ. 2569 ณ.28 ก.พ.2569 | C39: 2 | D39: P | F39: ร้อยละ | G39: 0.5 | H39: 85 | I39: 77 | J39: 79 | K39: 81 | L39: 83 | M39: 85 | N39: =ผลงานรวมทีม!E28 -> 98.13 | O39: =((Q39/5)*G39) -> 0.5 | Q39: =IF(N39=0,0,IF(N39>=M39,5,IF(N39>=L39,5-ABS(M39-N39)/(M39-L39),IF(N39>=K39,4-ABS(L39-N39)/(L39-K39),IF(N39>=J39,3-ABS(K39-N39)/(K39-J39),IF(N39>=I39,2-ABS(J39-N39)/(J39-I39),1)))))) -> 5
A40: 7.12อัตรารับชำระหนี้ถึงกำหนดเดือน มี.ค. 2569 ณ.31 มี.ค.2569 | C40: 2 | D40: P | F40: ร้อยละ | G40: 0.5 | H40: 90 | I40: 82 | J40: 84 | K40: 86 | L40: 88 | M40: 90 | N40: =ผลงานรวมทีม!E29 -> 93.47 | O40: =((Q40/5)*G40) -> 0.5 | Q40: =IF(N40=0,0,IF(N40>=M40,5,IF(N40>=L40,5-ABS(M40-N40)/(M40-L40),IF(N40>=K40,4-ABS(L40-N40)/(L40-K40),IF(N40>=J40,3-ABS(K40-N40)/(K40-J40),IF(N40>=I40,2-ABS(J40-N40)/(J40-I40),1)))))) -> 5
A41: 8. อัตรารับชำระหนี้ (สำรอง 1%) เดือน เม.ย. 68 - ม.ค. 69 ณ.สิ้นเดือนที่ 2 นับถัดจากเดือนที่ถึงกำหนดชำระ | Q41: =IF(N41=0,0,IF(N41>=M41,5,IF(N41>=L41,5-ABS(M41-N41)/(M41-L41),IF(N41>=K41,4-ABS(L41-N41)/(L41-K41),IF(N41>=J41,3-ABS(K41-N41)/(K41-J41),IF(N41>=I41,2-ABS(J41-N41)/(J41-I41),1)))))) -> 0
A42: 8.1อัตรารับชำระหนี้ถึงกำหนด(สำรอง 1%) เดือน เม.ย. 2568 ณ.30 มิ.ย.2568 | C42: 2 | E42: P | F42: ร้อยละ | G42: 0.5 | H42: 90 | I42: 82 | J42: 84 | K42: 86 | L42: 88 | M42: 90 | N42: =ผลงานรายเขต!E31 -> 93.04 | O42: =((Q42/5)*G42) -> 0.5 | Q42: =IF(N42=0,0,IF(N42>=M42,5,IF(N42>=L42,5-ABS(M42-N42)/(M42-L42),IF(N42>=K42,4-ABS(L42-N42)/(L42-K42),IF(N42>=J42,3-ABS(K42-N42)/(K42-J42),IF(N42>=I42,2-ABS(J42-N42)/(J42-I42),1)))))) -> 5
A43: 8.2อัตรารับชำระหนี้ถึงกำหนด(สำรอง 1%) พ.ค. 2568 ณ.31 ก.ค.2568 | C43: 2 | E43: P | F43: ร้อยละ | G43: 0.5 | H43: 90 | I43: 82 | J43: 84 | K43: 86 | L43: 88 | M43: 90 | N43: =ผลงานรายเขต!E32 -> 93.22 | O43: =((Q43/5)*G43) -> 0.5 | Q43: =IF(N43=0,0,IF(N43>=M43,5,IF(N43>=L43,5-ABS(M43-N43)/(M43-L43),IF(N43>=K43,4-ABS(L43-N43)/(L43-K43),IF(N43>=J43,3-ABS(K43-N43)/(K43-J43),IF(N43>=I43,2-ABS(J43-N43)/(J43-I43),1)))))) -> 5
A44: 8.3อัตรารับชำระหนี้ถึงกำหนด(สำรอง 1%) มิ.ย. 2568 ณ.31 ส.ค.2568 | C44: 2 | E44: P | F44: ร้อยละ | G44: 0.5 | H44: 90 | I44: 82 | J44: 84 | K44: 86 | L44: 88 | M44: 90 | N44: =ผลงานรายเขต!E33 -> 83.1 | O44: =((Q44/5)*G44) -> 0.155 | Q44: =IF(N44=0,0,IF(N44>=M44,5,IF(N44>=L44,5-ABS(M44-N44)/(M44-L44),IF(N44>=K44,4-ABS(L44-N44)/(L44-K44),IF(N44>=J44,3-ABS(K44-N44)/(K44-J44),IF(N44>=I44,2-ABS(J44-N44)/(J44-I44),1)))))) -> 1.55
...

Sheet ผลงานรวมทีม
A1: ผล | B1: STS. | C1: SCR. | D1: TARGET | E1: ACTUAL | F1: UNIT
A2: 1. ผลการดำเนินงาน (Key Performance)
A3: 1. ฟื้นฟูศักยภาพลูกค้าพักชำระหนี้
A4: 1.1 ผู้ผ่านการพัฒนา (30/09/68) | C4: 2.00/2 | D4: 159 | E4: 170 | F4: ราย
A5: 1.2 ผู้ผ่านการพัฒนา รายได้เพิ่ม/ต้นทุนลด หรือผลผลิตเพิ่ม ≥ 15% (30/03/69) | C5: 2.00/2 | D5: 159 | E5: 168 | F5: ราย
A6: 2. พัฒนา SME เกษตรหัวขบวน
A7: 2.1 SME เกษตรหัวขบวน (31/03/69) | C7: 1.50/1.5 | D7: 1 | E7: 1 | F7: ราย
A8: 2.2 SME เกษตรหัวขบวน รายได้/ปริมาณธุรกิจ เพิ่ม ≥ 10% (31/03/69) | C8: 1.50/1.5 | D8: 1 | E8: 1 | F8: ราย
A9: 3. สินเชื่อ ESG (30/03/69) | C9: 4.00/4 | D9: 4.05 | E9: 20 | F9: ล้านบาท
A10: 4. เพิ่มฐานลูกค้าสินเชื่อเกษตรกรกลุ่มใหม่ (30/03/69) | C10: 5.00/5 | D10: 47 | E10: 57 | F10: ราย
A11: 5. อนุมัติสินเชื่อใหม่ลูกค้าบุคคลธรรมดาและเกษตรกร S2 (30/03/69) | C11: 5.00/5 | D11: 280 | E11: 331 | F11: ราย
A12: 6. ทายาททดแทน (28/02/69) | C12: 5.00/5 | D12: 2 | E12: 3 | F12: ราย
A13: 7. การเติบโตสินเชื่อ
A14: 7.1 Secure Loans (30/03/69) | C14: 7.00/7 | D14: 8.73 | E14: 10.28 | F14: ล้านบาท
A15: 7.2 Normal Loans (30/03/69) | C15: 1.40/7 | D15: 8.45 | E15: -204.38 | F15: ล้านบาท
A16: 8. หนี้ถึงกำหนด
A17: 8.1 อัตรารับชำระหนี้
A18: 8.1.1 งวดชำระเดือน เม.ย. 68 (30/04/68) | C18: 0.15/0.15 | D18: 85 | E18: 93.04 | F18: ร้อยละ
A19: 8.1.2 งวดชำระเดือน พ.ค. 68 (31/05/68) | C19: 0.15/0.15 | D19: 85 | E19: 93.22 | F19: ร้อยละ
A20: 8.1.3 งวดชำระเดือน มิ.ย. 68 (30/06/68) | C20: 0.16/0.2 | D20: 85 | E20: 83.1 | F20: ร้อยละ
A21: 8.1.4 งวดชำระเดือน ก.ค. 68 (31/07/68) | C21: 0.15/0.15 | D21: 85 | E21: 93.54 | F21: ร้อยละ
A22: 8.1.5 งวดชำระเดือน ส.ค. 68 (31/08/68) | C22: 0.15/0.15 | D22: 85 | E22: 93.89 | F22: ร้อยละ
A23: 8.1.6 งวดชำระเดือน ก.ย. 68 (30/09/68) | C23: 0.20/0.2 | D23: 85 | E23: 99.51 | F23: ร้อยละ
A24: 8.1.7 งวดชำระเดือน ต.ค. 68 (31/10/68) | C24: 0.15/0.15 | D24: 85 | E24: 97.86 | F24: ร้อยละ
A25: 8.1.8 งวดชำระเดือน พ.ย. 68 (30/11/68) | C25: 0.15/0.15 | D25: 85 | E25: 97.99 | F25: ร้อยละ
A26: 8.1.9 งวดชำระเดือน ธ.ค. 68 (31/12/68) | C26: 0.20/0.2 | D26: 85 | E26: 86.99 | F26: ร้อยละ
A27: 8.1.10 งวดชำระเดือน ม.ค. 69 (31/01/69) | C27: 0.15/0.15 | D27: 85 | E27: 97.53 | F27: ร้อยละ
A28: 8.1.11 งวดชำระเดือน ก.พ. 69 (28/02/69) | C28: 0.15/0.15 | D28: 85 | E28: 98.13 | F28: ร้อยละ
A29: 8.1.12 งวดชำระเดือน มี.ค. 69 (31/03/69) | C29: 0.15/0.2 | D29: 90 | E29: 93.47 | F29: ร้อยละ
A30: 8.2 อัตรารับชำระหนี้ (สำรอง 1%)
A31: 8.2.1 งวดชำระเดือน เม.ย. 68 ณ สิ้นเดือน มิ.ย. 68 (30/06/68) | C31: 0.50/0.5 | D31: 90 | E31: 100 | F31: ร้อยละ
A32: 8.2.2 งวดชำระเดือน พ.ค. 68 ณ สิ้นเดือน ก.ค. 68 (31/07/68) | C32: 0.50/0.5 | D32: 90 | E32: 100 | F32: ร้อยละ
A33: 8.2.3 งวดชำระเดือน มิ.ย. 68 ณ สิ้นเดือน ส.ค. 68 (31/08/68) | C33: 0.75/0.75 | D33: 90 | E33: 97.4 | F33: ร้อยละ
A34: 8.2.4 งวดชำระเดือน ก.ค. 68 ณ สิ้นเดือน ก.ย. 68 (30/09/68) | C34: 0.50/0.5 | D34: 90 | E34: 100 | F34: ร้อยละ
A35: 8.2.5 งวดชำระเดือน ส.ค. 68 ณ สิ้นเดือน ต.ค. 68 (31/10/68) | C35: 0.50/0.5 | D35: 90 | E35: 100 | F35: ร้อยละ
A36: 8.2.6 งวดชำระเดือน ก.ย. 68 ณ สิ้นเดือน พ.ย. 68 (30/11/68) | C36: 0.75/0.75 | D36: 90 | E36: 100 | F36: ร้อยละ
A37: 8.2.7 งวดชำระเดือน ต.ค. 68 ณ สิ้นเดือน ธ.ค. 68 (31/12/68) | C37: 0.50/0.5 | D37: 90 | E37: 100 | F37: ร้อยละ
A38: 8.2.8 งวดชำระเดือน พ.ย. 68 ณ สิ้นเดือน ม.ค. 69 (31/01/69) | C38: 0.50/0.5 | D38: 90 | E38: 100 | F38: ร้อยละ
A39: 8.2.9 งวดชำระเดือน ธ.ค. 68 ณ สิ้นเดือน ก.พ. 69 (28/02/69) | C39: 0.75/0.75 | D39: 90 | E39: 99.79 | F39: ร้อยละ
A40: 8.2.10 งวดชำระเดือน ม.ค. 69 ณ สิ้นเดือน มี.ค. 69 (30/03/69) | C40: 0.75/0.75 | D40: 90 | E40: 99.88 | F40: ร้อยละ
...

Sheet ผลงานรายเขต
A1: ผล | B1: STS. | C1: SCR. | D1: TARGET | E1: พิราวรรณ | F1: พรพงศ์
A2: 1. ผลการดำเนินงาน (Key Performance)
A3: 1. ฟื้นฟูศักยภาพลูกค้าพักชำระหนี้
A4: 1.1 ผู้ผ่านการพัฒนา (30/09/68) | C4: 2.00/2 | D4: 159 | E4: 170 | F4: 170 | G4: ราย
A5: 1.2 ผู้ผ่านการพัฒนา รายได้เพิ่ม/ต้นทุนลด หรือผลผลิตเพิ่ม ≥ 15% (30/03/69) | C5: 2.00/2 | D5: 159 | E5: 168 | F5: 168 | G5: ราย
A6: 2. พัฒนา SME เกษตรหัวขบวน
A7: 2.1 SME เกษตรหัวขบวน (31/03/69) | C7: 1.50/1.5 | D7: 1 | E7: 1 | F7: 1 | G7: ราย
A8: 2.2 SME เกษตรหัวขบวน รายได้/ปริมาณธุรกิจ เพิ่ม ≥ 10% (31/03/69) | C8: 1.50/1.5 | D8: 1 | E8: 1 | F8: 1 | G8: ราย
A9: 3. สินเชื่อ ESG (30/03/69) | C9: 4.00/4 | D9: 4.05 | E9: 20 | F9: 20 | G9: ล้านบาท
A10: 4. เพิ่มฐานลูกค้าสินเชื่อเกษตรกรกลุ่มใหม่ (30/03/69) | C10: 5.00/5 | D10: 47 | E10: 57 | F10: 57 | G10: ราย
A11: 5. อนุมัติสินเชื่อใหม่ลูกค้าบุคคลธรรมดาและเกษตรกร S2 (31/03/69) | C11: 5.00/5 | D11: 280 | E11: 331 | F11: 333 | G11: ราย
A12: 6. ทายาททดแทน (28/02/69) | C12: 5.00/5 | D12: 2 | E12: 3 | F12: 3 | G12: ราย
A13: 7. การเติบโตสินเชื่อ
A14: 7.1 Secure Loans (31/03/69) | C14: 7.00/7 | D14: 8.73 | E14: 10.28 | F14: 10.27 | G14: ล้านบาท
A15: 7.2 Normal Loans (31/03/69) | C15: 1.40/7 | D15: 8.45 | E15: -204.38 | F15: -204 | G15: ล้านบาท
A16: 8. หนี้ถึงกำหนด
A17: 8.1 อัตรารับชำระหนี้
A18: 8.1.1 งวดชำระเดือน เม.ย. 68 (30/04/68) | C18: 0.15/0.15 | D18: 85 | E18: 93.04 | F18: 93.04 | G18: ร้อยละ
A19: 8.1.2 งวดชำระเดือน พ.ค. 68 (31/05/68) | C19: 0.15/0.15 | D19: 85 | E19: 93.22 | F19: 93.22 | G19: ร้อยละ
A20: 8.1.3 งวดชำระเดือน มิ.ย. 68 (30/06/68) | C20: 0.16/0.2 | D20: 85 | E20: 83.1 | F20: 83.1 | G20: ร้อยละ
A21: 8.1.4 งวดชำระเดือน ก.ค. 68 (31/07/68) | C21: 0.15/0.15 | D21: 85 | E21: 93.54 | F21: 93.54 | G21: ร้อยละ
A22: 8.1.5 งวดชำระเดือน ส.ค. 68 (31/08/68) | C22: 0.15/0.15 | D22: 85 | E22: 93.89 | F22: 93.89 | G22: ร้อยละ
A23: 8.1.6 งวดชำระเดือน ก.ย. 68 (30/09/68) | C23: 0.20/0.2 | D23: 85 | E23: 99.51 | F23: 99.51 | G23: ร้อยละ
A24: 8.1.7 งวดชำระเดือน ต.ค. 68 (31/10/68) | C24: 0.15/0.15 | D24: 85 | E24: 100 | F24: 100 | G24: ร้อยละ
A25: 8.1.8 งวดชำระเดือน พ.ย. 68 (30/11/68) | C25: 0.15/0.15 | D25: 85 | E25: 100 | F25: 100 | G25: ร้อยละ
A26: 8.1.9 งวดชำระเดือน ธ.ค. 68 (31/12/68) | C26: 0.20/0.2 | D26: 85 | E26: 77.01 | F26: 87.54 | G26: ร้อยละ
A27: 8.1.10 งวดชำระเดือน ม.ค. 69 (31/01/69) | C27: 0.15/0.15 | D27: 85 | E27: 99.1 | F27: 95.32 | G27: ร้อยละ
A28: 8.1.11 งวดชำระเดือน ก.พ. 69 (28/02/69) | C28: 0.15/0.15 | D28: 85 | E28: 100 | F28: 99.77 | G28: ร้อยละ
A29: 8.1.12 งวดชำระเดือน มี.ค. 69 (31/03/69) | C29: 0.15/0.2 | D29: 90 | E29: 91.14 | F29: 83.71 | G29: ร้อยละ
A30: 8.2 อัตรารับชำระหนี้ (สำรอง 1%)
A31: 8.2.1 งวดชำระเดือน เม.ย. 68 ณ สิ้นเดือน มิ.ย. 68 (30/06/68) | C31: 0.50/0.5 | D31: 90 | E31: 93.04 | F31: 93.04 | G31: ร้อยละ
A32: 8.2.2 งวดชำระเดือน พ.ค. 68 ณ สิ้นเดือน ก.ค. 68 (31/07/68) | C32: 0.50/0.5 | D32: 90 | E32: 93.22 | F32: 93.22 | G32: ร้อยละ
A33: 8.2.3 งวดชำระเดือน มิ.ย. 68 ณ สิ้นเดือน ส.ค. 68 (31/08/68) | C33: 0.75/0.75 | D33: 90 | E33: 83.1 | F33: 83.1 | G33: ร้อยละ
A34: 8.2.4 งวดชำระเดือน ก.ค. 68 ณ สิ้นเดือน ก.ย. 68 (30/09/68) | C34: 0.50/0.5 | D34: 90 | E34: 100 | F34: 98.54 | G34: ร้อยละ
A35: 8.2.5 งวดชำระเดือน ส.ค. 68 ณ สิ้นเดือน ต.ค. 68 (31/10/68) | C35: 0.50/0.5 | D35: 90 | E35: 100 | F35: 100 | G35: ร้อยละ
A36: 8.2.6 งวดชำระเดือน ก.ย. 68 ณ สิ้นเดือน พ.ย. 68 (30/11/68) | C36: 0.75/0.75 | D36: 90 | E36: 100 | F36: 99.18 | G36: ร้อยละ
A37: 8.2.7 งวดชำระเดือน ต.ค. 68 ณ สิ้นเดือน ธ.ค. 68 (31/12/68) | C37: 0.50/0.5 | D37: 90 | E37: 100 | F37: 100 | G37: ร้อยละ
A38: 8.2.8 งวดชำระเดือน พ.ย. 68 ณ สิ้นเดือน ม.ค. 69 (31/01/69) | C38: 0.50/0.5 | D38: 90 | E38: 100 | F38: 100 | G38: ร้อยละ
A39: 8.2.9 งวดชำระเดือน ธ.ค. 68 ณ สิ้นเดือน ก.พ. 69 (28/02/69) | C39: 0.75/0.75 | D39: 90 | E39: 100 | F39: 99.18 | G39: ร้อยละ
A40: 8.2.10 งวดชำระเดือน ม.ค. 69 ณ สิ้นเดือน มี.ค. 69 (30/03/69) | C40: 0.75/0.75 | D40: 90 | E40: 100 | F40: 99.71 | G40: ร้อยละ
...
